<?xml version="1.0"?>
<robot name="robot">
  <!-- Define the base link -->
  <link name="base_link">
    <visual>
      <geometry>
        <box size="0.5 0.3 0.1"/>
      </geometry>
      <material name="blue"/>
    </visual>
    <collision>
      <geometry>
        <box size="0.5 0.3 0.1"/>
      </geometry>
    </collision>
  </link>

  <!-- Define the front wheel -->
  <link name="front_wheel">
    <visual>
      <geometry>
        <cylinder radius="0.1" length="0.05"/>
      </geometry>
      <material name="black"/>
    </visual>
    <collision>
      <geometry>
        <cylinder radius="0.1" length="0.05"/>
      </geometry>
    </collision>
  </link>

  <!-- Define the joint between the base and the front wheel -->
  <joint name="front_wheel_joint" type="revolute">
    <parent link="base_link"/>
    <child link="front_wheel"/>
    <origin xyz="0.25 0.15 0" rpy="0 0 0"/>
    <axis xyz="0 0 1"/>
    <limit effort="100" lower="-1.0" upper="1.0" velocity="1.0"/>
  </joint>

  <!-- Define other joints and links here -->

</robot>

